2024-06-22 01:25:13,849 - src.service.graph_experiments - ERROR - 'ExperimentsImpl' object has no attribute 'phase'
2024-06-22 01:25:13,850 - src.service.graph_experiments - ERROR - Traceback (most recent call last):
  File "/Users/phamminhlong/Desktop/paper/src/service/graph_experiments.py", line 40, in run
    if self.phase == 'train':
AttributeError: 'ExperimentsImpl' object has no attribute 'phase'

2024-06-22 01:25:13,850 - src.utils.timer - INFO - DONE PROCESS PHASE EXPERIMENT IN 0.0004s
2024-06-22 01:26:22,417 - src.service.graph_experiments - INFO - Start training !
2024-06-22 01:26:22,556 - src.service.graph_experiments - ERROR - Expected a 'Data', 'HeteroData', or a tuple of 'FeatureStore' and 'GraphStore' (got '<class 'src.service.data_loader.EllipticLoader'>')
2024-06-22 01:26:22,559 - src.service.graph_experiments - ERROR - Traceback (most recent call last):
  File "/Users/phamminhlong/Desktop/paper/src/service/graph_train.py", line 77, in fit
    input_nodes=self.data_loader.train_mask,
AttributeError: 'EllipticLoader' object has no attribute 'train_mask'

During handling of the above exception, another exception occurred:

Traceback (most recent call last):
  File "/Users/phamminhlong/Desktop/paper/src/service/graph_experiments.py", line 43, in run
    self.trainer.fit()
  File "/Users/phamminhlong/Desktop/paper/src/utils/timer.py", line 30, in wraper
    result = func(*args, **kwargs)
  File "/Users/phamminhlong/Desktop/paper/src/service/graph_train.py", line 83, in fit
    loader = NeighborLoader(
  File "/Users/phamminhlong/miniconda3/envs/mlops/lib/python3.8/site-packages/torch_geometric/loader/neighbor_loader.py", line 229, in __init__
    neighbor_sampler = NeighborSampler(
  File "/Users/phamminhlong/miniconda3/envs/mlops/lib/python3.8/site-packages/torch_geometric/sampler/neighbor_sampler.py", line 66, in __init__
    self.data_type = DataType.from_data(data)
  File "/Users/phamminhlong/miniconda3/envs/mlops/lib/python3.8/site-packages/torch_geometric/sampler/base.py", line 36, in from_data
    raise ValueError(f"Expected a 'Data', 'HeteroData', or a tuple of "
ValueError: Expected a 'Data', 'HeteroData', or a tuple of 'FeatureStore' and 'GraphStore' (got '<class 'src.service.data_loader.EllipticLoader'>')

2024-06-22 01:26:22,559 - src.utils.timer - INFO - DONE PROCESS PHASE EXPERIMENT IN 0.1425s
2024-06-22 19:41:55,459 - src.service.graph_experiments - INFO - Start training !
2024-06-22 19:41:55,603 - src.service.graph_experiments - ERROR - Expected a 'Data', 'HeteroData', or a tuple of 'FeatureStore' and 'GraphStore' (got '<class 'src.service.data_loader.EllipticLoader'>')
2024-06-22 19:41:55,606 - src.service.graph_experiments - ERROR - Traceback (most recent call last):
  File "/Users/phamminhlong/Desktop/paper/src/service/graph_train.py", line 77, in fit
    input_nodes=self.data_loader.train_mask,
AttributeError: 'EllipticLoader' object has no attribute 'train_mask'

During handling of the above exception, another exception occurred:

Traceback (most recent call last):
  File "/Users/phamminhlong/Desktop/paper/src/service/graph_experiments.py", line 43, in run
    self.trainer.fit()
  File "/Users/phamminhlong/Desktop/paper/src/utils/timer.py", line 30, in wraper
    result = func(*args, **kwargs)
  File "/Users/phamminhlong/Desktop/paper/src/service/graph_train.py", line 83, in fit
    loader = NeighborLoader(
  File "/Users/phamminhlong/miniconda3/envs/mlops/lib/python3.8/site-packages/torch_geometric/loader/neighbor_loader.py", line 229, in __init__
    neighbor_sampler = NeighborSampler(
  File "/Users/phamminhlong/miniconda3/envs/mlops/lib/python3.8/site-packages/torch_geometric/sampler/neighbor_sampler.py", line 66, in __init__
    self.data_type = DataType.from_data(data)
  File "/Users/phamminhlong/miniconda3/envs/mlops/lib/python3.8/site-packages/torch_geometric/sampler/base.py", line 36, in from_data
    raise ValueError(f"Expected a 'Data', 'HeteroData', or a tuple of "
ValueError: Expected a 'Data', 'HeteroData', or a tuple of 'FeatureStore' and 'GraphStore' (got '<class 'src.service.data_loader.EllipticLoader'>')

2024-06-22 19:41:55,606 - src.utils.timer - INFO - DONE PROCESS PHASE EXPERIMENT IN 0.1467s
2024-06-22 22:01:51,097 - src.utils.timer - INFO - DONE PROCESS PHASE ELLIPTIC LOADER IN 1.1790s
2024-06-22 22:01:51,100 - src.service.graph_experiments - INFO - Start training !
2024-06-22 22:01:51,571 - src.service.graph_experiments - ERROR - Expected a 'Data', 'HeteroData', or a tuple of 'FeatureStore' and 'GraphStore' (got '<class 'src.data_model.network.DataNetWork'>')
2024-06-22 22:01:51,574 - src.service.graph_experiments - ERROR - Traceback (most recent call last):
  File "/Users/phamminhlong/Desktop/paper/src/service/graph_train.py", line 74, in fit
    loader = NeighborLoader(
  File "/Users/phamminhlong/miniconda3/envs/mlops/lib/python3.8/site-packages/torch_geometric/loader/neighbor_loader.py", line 229, in __init__
    neighbor_sampler = NeighborSampler(
  File "/Users/phamminhlong/miniconda3/envs/mlops/lib/python3.8/site-packages/torch_geometric/sampler/neighbor_sampler.py", line 66, in __init__
    self.data_type = DataType.from_data(data)
  File "/Users/phamminhlong/miniconda3/envs/mlops/lib/python3.8/site-packages/torch_geometric/sampler/base.py", line 36, in from_data
    raise ValueError(f"Expected a 'Data', 'HeteroData', or a tuple of "
ValueError: Expected a 'Data', 'HeteroData', or a tuple of 'FeatureStore' and 'GraphStore' (got '<class 'src.data_model.network.DataNetWork'>')

During handling of the above exception, another exception occurred:

Traceback (most recent call last):
  File "/Users/phamminhlong/Desktop/paper/src/service/graph_experiments.py", line 43, in run
    self.trainer.fit()
  File "/Users/phamminhlong/Desktop/paper/src/utils/timer.py", line 30, in wraper
    result = func(*args, **kwargs)
  File "/Users/phamminhlong/Desktop/paper/src/service/graph_train.py", line 83, in fit
    loader = NeighborLoader(
  File "/Users/phamminhlong/miniconda3/envs/mlops/lib/python3.8/site-packages/torch_geometric/loader/neighbor_loader.py", line 229, in __init__
    neighbor_sampler = NeighborSampler(
  File "/Users/phamminhlong/miniconda3/envs/mlops/lib/python3.8/site-packages/torch_geometric/sampler/neighbor_sampler.py", line 66, in __init__
    self.data_type = DataType.from_data(data)
  File "/Users/phamminhlong/miniconda3/envs/mlops/lib/python3.8/site-packages/torch_geometric/sampler/base.py", line 36, in from_data
    raise ValueError(f"Expected a 'Data', 'HeteroData', or a tuple of "
ValueError: Expected a 'Data', 'HeteroData', or a tuple of 'FeatureStore' and 'GraphStore' (got '<class 'src.data_model.network.DataNetWork'>')

2024-06-22 22:01:51,574 - src.utils.timer - INFO - DONE PROCESS PHASE EXPERIMENT IN 0.4743s
2024-06-22 23:36:25,175 - src.utils.timer - INFO - DONE PROCESS PHASE ELLIPTIC LOADER IN 1.2180s
2024-06-22 23:37:50,872 - src.utils.timer - INFO - DONE PROCESS PHASE ELLIPTIC LOADER IN 1.2436s
2024-06-22 23:40:33,588 - src.utils.timer - INFO - DONE PROCESS PHASE ELLIPTIC LOADER IN 1.2134s
2024-06-22 23:40:33,591 - src.service.graph_experiments - INFO - Start training !
2024-06-22 23:40:33,641 - src.service.graph_experiments - ERROR - 'int' object is not iterable
2024-06-22 23:40:33,643 - src.service.graph_experiments - ERROR - Traceback (most recent call last):
  File "/Users/phamminhlong/Desktop/paper/src/service/graph_experiments.py", line 43, in run
    self.trainer.fit()
  File "/Users/phamminhlong/Desktop/paper/src/utils/timer.py", line 30, in wraper
    result = func(*args, **kwargs)
  File "/Users/phamminhlong/Desktop/paper/src/service/graph_train.py", line 96, in fit
    for epoch in tqdm.tqdm(self.epochs, colour='green', desc='Training graph model'):
  File "/Users/phamminhlong/miniconda3/envs/mlops/lib/python3.8/site-packages/tqdm/std.py", line 1195, in __iter__
    for obj in iterable:
TypeError: 'int' object is not iterable

2024-06-22 23:40:33,643 - src.utils.timer - INFO - DONE PROCESS PHASE EXPERIMENT IN 0.0527s
2024-06-22 23:41:03,106 - src.utils.timer - INFO - DONE PROCESS PHASE ELLIPTIC LOADER IN 0.5683s
2024-06-22 23:41:03,108 - src.service.graph_experiments - INFO - Start training !
2024-06-22 23:41:03,153 - src.service.graph_experiments - ERROR - local variable 'loader' referenced before assignment
2024-06-22 23:41:03,155 - src.service.graph_experiments - ERROR - Traceback (most recent call last):
  File "/Users/phamminhlong/Desktop/paper/src/service/graph_experiments.py", line 43, in run
    self.trainer.fit()
  File "/Users/phamminhlong/Desktop/paper/src/utils/timer.py", line 30, in wraper
    result = func(*args, **kwargs)
  File "/Users/phamminhlong/Desktop/paper/src/service/graph_train.py", line 104, in fit
    for i, batch in enumerate(loader):
UnboundLocalError: local variable 'loader' referenced before assignment

2024-06-22 23:41:03,155 - src.utils.timer - INFO - DONE PROCESS PHASE EXPERIMENT IN 0.0466s
2024-06-22 23:47:17,769 - src.utils.timer - INFO - DONE PROCESS PHASE ELLIPTIC LOADER IN 1.2231s
2024-06-22 23:47:17,772 - src.service.graph_experiments - INFO - Start training !
2024-06-22 23:47:17,820 - src.service.graph_experiments - ERROR - 'DataNetWork' object is not iterable
2024-06-22 23:47:17,822 - src.service.graph_experiments - ERROR - Traceback (most recent call last):
  File "/Users/phamminhlong/Desktop/paper/src/service/graph_experiments.py", line 43, in run
    self.trainer.fit()
  File "/Users/phamminhlong/Desktop/paper/src/utils/timer.py", line 30, in wraper
    result = func(*args, **kwargs)
  File "/Users/phamminhlong/Desktop/paper/src/service/graph_train.py", line 107, in fit
    for i, batch in enumerate(loader):
TypeError: 'DataNetWork' object is not iterable

2024-06-22 23:47:17,822 - src.utils.timer - INFO - DONE PROCESS PHASE EXPERIMENT IN 0.0506s
2024-06-22 23:48:27,448 - src.utils.timer - INFO - DONE PROCESS PHASE ELLIPTIC LOADER IN 1.1384s
2024-06-22 23:48:27,452 - src.service.graph_experiments - INFO - Start training !
2024-06-22 23:48:27,500 - src.service.graph_experiments - ERROR - 'DataNetWork' object is not iterable
2024-06-22 23:48:27,506 - src.service.graph_experiments - ERROR - Traceback (most recent call last):
  File "/Users/phamminhlong/Desktop/paper/src/service/graph_experiments.py", line 43, in run
    self.trainer.fit()
  File "/Users/phamminhlong/Desktop/paper/src/utils/timer.py", line 30, in wraper
    result = func(*args, **kwargs)
  File "/Users/phamminhlong/Desktop/paper/src/service/graph_train.py", line 108, in fit
    for i, batch in enumerate(loader):
TypeError: 'DataNetWork' object is not iterable

2024-06-22 23:48:27,506 - src.utils.timer - INFO - DONE PROCESS PHASE EXPERIMENT IN 0.0542s
